2018-01-30 21:56:09,678 - root - INFO - logging配置文件路径是/Users/tianqi/Desktop/study/Appium_UI_Autotest/Config/log_config.json
2018-01-30 21:56:09,680 - root - INFO - waiting
2018-01-30 21:56:29,686 - root - INFO - in page
2018-01-30 21:56:29,782 - root - INFO - click
2018-01-30 21:56:30,766 - root - INFO - waiting
2018-01-30 21:56:40,772 - root - INFO - navagite
2018-01-30 21:56:40,773 - root - INFO - in page
2018-01-30 21:56:40,798 - root - INFO - input
2018-01-30 21:56:47,297 - root - INFO - input
2018-01-30 21:56:53,175 - root - INFO - click
2018-01-30 21:56:53,989 - root - INFO - waiting
2018-01-30 21:57:03,996 - root - INFO - navagite
2018-01-30 21:57:03,997 - root - INFO - in page
2018-01-30 21:57:39,838 - root - INFO - logging配置文件路径是/Users/tianqi/Desktop/study/Appium_UI_Autotest/Config/log_config.json
2018-01-30 21:57:39,844 - root - INFO - waiting
2018-01-30 21:57:59,850 - root - INFO - in page
2018-01-30 21:57:59,888 - root - INFO - click
2018-01-30 21:58:00,497 - root - INFO - waiting
2018-01-30 21:58:10,504 - root - INFO - navagite
2018-01-30 21:58:10,505 - root - INFO - in page
2018-01-30 21:58:10,544 - root - INFO - input
2018-01-30 21:58:17,314 - root - INFO - input
2018-01-30 21:58:23,578 - root - INFO - click
2018-01-30 21:58:24,448 - root - INFO - waiting
2018-01-30 21:58:34,453 - root - INFO - navagite
2018-01-30 21:58:34,454 - root - INFO - in page
2018-01-30 21:58:34,563 - root - ERROR - can not find elementcom.sina.weibo:id/tv_groupName
2018-01-30 21:58:34,565 - root - ERROR - not in page HomePage
2018-01-30 22:00:45,403 - root - INFO - logging配置文件路径是/Users/tianqi/Desktop/study/Appium_UI_Autotest/Config/log_config.json
2018-01-30 22:00:45,405 - root - INFO - waiting
2018-01-30 22:01:05,413 - root - INFO - in page
2018-01-30 22:01:05,515 - root - INFO - click
2018-01-30 22:01:06,028 - root - INFO - waiting
2018-01-30 22:01:16,034 - root - INFO - navagite
2018-01-30 22:01:16,035 - root - INFO - in page
2018-01-30 22:01:16,165 - root - INFO - input
2018-01-30 22:01:22,483 - root - INFO - input
2018-01-30 22:01:27,880 - root - INFO - click
2018-01-30 22:01:28,714 - root - INFO - waiting
2018-01-30 22:01:38,719 - root - INFO - navagite
2018-01-30 22:01:38,721 - root - INFO - in page
2018-01-30 22:02:27,903 - root - INFO - logging配置文件路径是/Users/tianqi/Desktop/study/Appium_UI_Autotest/Config/log_config.json
2018-01-30 22:04:18,121 - root - INFO - logging配置文件路径是/Users/tianqi/Desktop/study/Appium_UI_Autotest/Config/log_config.json
2018-01-30 22:04:28,971 - root - INFO - logging配置文件路径是/Users/tianqi/Desktop/study/Appium_UI_Autotest/Config/log_config.json
2018-01-30 22:04:28,972 - root - INFO - waiting
2018-01-30 22:06:49,923 - root - INFO - logging配置文件路径是/Users/tianqi/Desktop/study/Appium_UI_Autotest/Config/log_config.json
2018-01-30 22:06:49,926 - root - INFO - waiting
2018-01-30 22:07:59,112 - root - INFO - logging配置文件路径是/Users/tianqi/Desktop/study/Appium_UI_Autotest/Config/log_config.json
2018-01-30 22:07:59,113 - root - INFO - waiting
2018-01-30 22:08:19,121 - root - ERROR - 注销过程中出现错误
Traceback (most recent call last):
  File "Test/steps/login_steps.py", line 19, in logout
    '''.format(home_page, my))
  File "/Library/Frameworks/Python.framework/Versions/3.5/lib/python3.5/site-packages/behave/runner.py", line 278, in execute_steps
    steps = self.feature.parser.parse_steps(steps_text)
  File "/Library/Frameworks/Python.framework/Versions/3.5/lib/python3.5/site-packages/behave/parser.py", line 531, in parse_steps
    self.action(line)
  File "/Library/Frameworks/Python.framework/Versions/3.5/lib/python3.5/site-packages/behave/parser.py", line 267, in action
    raise ParserError(msg, None, self.filename)
behave.parser.ParserError: Failed to parse <string>: 
Parser failure in state steps, at line 2: 'click <Page.Home.home_page.HomePage object at 0x1032cd9e8> in ('accessibility id', '我的资料')'

2018-01-30 22:09:12,991 - root - INFO - logging配置文件路径是/Users/tianqi/Desktop/study/Appium_UI_Autotest/Config/log_config.json
2018-01-30 22:09:12,995 - root - INFO - waiting
2018-01-30 22:09:33,001 - root - ERROR - 注销过程中出现错误
Traceback (most recent call last):
  File "Test/steps/login_steps.py", line 19, in logout
    '''.format(my, home_page))
  File "/Library/Frameworks/Python.framework/Versions/3.5/lib/python3.5/site-packages/behave/runner.py", line 278, in execute_steps
    steps = self.feature.parser.parse_steps(steps_text)
  File "/Library/Frameworks/Python.framework/Versions/3.5/lib/python3.5/site-packages/behave/parser.py", line 531, in parse_steps
    self.action(line)
  File "/Library/Frameworks/Python.framework/Versions/3.5/lib/python3.5/site-packages/behave/parser.py", line 267, in action
    raise ParserError(msg, None, self.filename)
behave.parser.ParserError: Failed to parse <string>: 
Parser failure in state steps, at line 2: 'click ('accessibility id', '我的资料') in <Page.Home.home_page.HomePage object at 0x1032cd7b8>'

2018-01-30 22:11:46,821 - root - INFO - logging配置文件路径是/Users/tianqi/Desktop/study/Appium_UI_Autotest/Config/log_config.json
2018-01-30 22:11:46,822 - root - INFO - waiting
2018-01-30 22:12:06,829 - root - ERROR - 注销过程中出现错误
Traceback (most recent call last):
  File "Test/steps/login_steps.py", line 15, in logout
    '''.format("my_profile", "HomePage"))
  File "/Library/Frameworks/Python.framework/Versions/3.5/lib/python3.5/site-packages/behave/runner.py", line 278, in execute_steps
    steps = self.feature.parser.parse_steps(steps_text)
  File "/Library/Frameworks/Python.framework/Versions/3.5/lib/python3.5/site-packages/behave/parser.py", line 531, in parse_steps
    self.action(line)
  File "/Library/Frameworks/Python.framework/Versions/3.5/lib/python3.5/site-packages/behave/parser.py", line 267, in action
    raise ParserError(msg, None, self.filename)
behave.parser.ParserError: Failed to parse <string>: 
Parser failure in state steps, at line 2: 'click my_profile in HomePage'

2018-01-30 22:13:11,196 - root - INFO - logging配置文件路径是/Users/tianqi/Desktop/study/Appium_UI_Autotest/Config/log_config.json
2018-01-30 22:13:11,198 - root - INFO - waiting
2018-01-30 22:13:31,206 - root - INFO - click
2018-01-30 22:14:06,778 - root - INFO - logging配置文件路径是/Users/tianqi/Desktop/study/Appium_UI_Autotest/Config/log_config.json
2018-01-30 22:14:06,785 - root - INFO - waiting
2018-01-30 22:14:26,791 - root - INFO - click
2018-01-30 22:15:07,510 - root - INFO - logging配置文件路径是/Users/tianqi/Desktop/study/Appium_UI_Autotest/Config/log_config.json
2018-01-30 22:15:07,511 - root - INFO - waiting
2018-01-30 22:15:27,518 - root - INFO - click
2018-01-30 23:18:15,201 - root - INFO - logging配置文件路径是/Users/tianqi/Desktop/study/Appium_UI_Autotest/Config/log_config.json
2018-01-30 23:18:15,202 - root - INFO - waiting
2018-01-30 23:18:35,206 - root - INFO - click
2018-01-30 23:18:35,334 - root - ERROR - 注销过程中出现错误
Traceback (most recent call last):
  File "Test/steps/login_steps.py", line 16, in logout
    '''.format("my_profile", "HomePage"))
  File "/Library/Frameworks/Python.framework/Versions/3.5/lib/python3.5/site-packages/behave/runner.py", line 287, in execute_steps
    assert False, message
AssertionError: FAILED SUB-STEP: When click my_profile in HomePage
Substep info: Traceback (most recent call last):
  File "/Library/Frameworks/Python.framework/Versions/3.5/lib/python3.5/site-packages/behave/model.py", line 1456, in run
    match.run(runner.context)
  File "/Library/Frameworks/Python.framework/Versions/3.5/lib/python3.5/site-packages/behave/model.py", line 1903, in run
    self.func(context, *args, **kwargs)
  File "Test/steps/base_steps.py", line 26, in click_element
    LocateHeper(context.driver).find(element).click()
  File "/Users/tianqi/Desktop/study/Appium_UI_Autotest/Util/locate_helper.py", line 55, in find
    element = self.driver.find_element(by=location[0], value=location[1])
  File "/Library/Frameworks/Python.framework/Versions/3.5/lib/python3.5/site-packages/selenium/webdriver/remote/webdriver.py", line 752, in find_element
    'value': value})['value']
  File "/Library/Frameworks/Python.framework/Versions/3.5/lib/python3.5/site-packages/selenium/webdriver/remote/webdriver.py", line 236, in execute
    self.error_handler.check_response(response)
  File "/Library/Frameworks/Python.framework/Versions/3.5/lib/python3.5/site-packages/appium/webdriver/errorhandler.py", line 29, in check_response
    raise wde
  File "/Library/Frameworks/Python.framework/Versions/3.5/lib/python3.5/site-packages/appium/webdriver/errorhandler.py", line 24, in check_response
    super(MobileErrorHandler, self).check_response(response)
  File "/Library/Frameworks/Python.framework/Versions/3.5/lib/python3.5/site-packages/selenium/webdriver/remote/errorhandler.py", line 192, in check_response
    raise exception_class(message, screen, stacktrace)
selenium.common.exceptions.NoSuchElementException: Message: An element could not be located on the page using the given search parameters.


2018-01-30 23:27:43,579 - root - INFO - logging配置文件路径是/Users/tianqi/Desktop/study/Appium_UI_Autotest/Config/log_config.json
2018-01-30 23:27:43,581 - root - INFO - waiting
2018-01-30 23:28:03,588 - root - INFO - click
2018-01-30 23:28:03,705 - root - ERROR - 注销过程中出现错误
Traceback (most recent call last):
  File "Test/steps/login_steps.py", line 16, in logout
    '''.format("my_profile", "HomePage"))
  File "/Library/Frameworks/Python.framework/Versions/3.5/lib/python3.5/site-packages/behave/runner.py", line 287, in execute_steps
    assert False, message
AssertionError: FAILED SUB-STEP: When click my_profile in HomePage
Substep info: Traceback (most recent call last):
  File "/Library/Frameworks/Python.framework/Versions/3.5/lib/python3.5/site-packages/behave/model.py", line 1456, in run
    match.run(runner.context)
  File "/Library/Frameworks/Python.framework/Versions/3.5/lib/python3.5/site-packages/behave/model.py", line 1903, in run
    self.func(context, *args, **kwargs)
  File "Test/steps/base_steps.py", line 26, in click_element
    LocateHeper(context.driver).find(element).click()
  File "/Users/tianqi/Desktop/study/Appium_UI_Autotest/Util/locate_helper.py", line 55, in find
    element = self.driver.find_element(by=location[0], value=location[1])
  File "/Library/Frameworks/Python.framework/Versions/3.5/lib/python3.5/site-packages/selenium/webdriver/remote/webdriver.py", line 752, in find_element
    'value': value})['value']
  File "/Library/Frameworks/Python.framework/Versions/3.5/lib/python3.5/site-packages/selenium/webdriver/remote/webdriver.py", line 236, in execute
    self.error_handler.check_response(response)
  File "/Library/Frameworks/Python.framework/Versions/3.5/lib/python3.5/site-packages/appium/webdriver/errorhandler.py", line 29, in check_response
    raise wde
  File "/Library/Frameworks/Python.framework/Versions/3.5/lib/python3.5/site-packages/appium/webdriver/errorhandler.py", line 24, in check_response
    super(MobileErrorHandler, self).check_response(response)
  File "/Library/Frameworks/Python.framework/Versions/3.5/lib/python3.5/site-packages/selenium/webdriver/remote/errorhandler.py", line 192, in check_response
    raise exception_class(message, screen, stacktrace)
selenium.common.exceptions.NoSuchElementException: Message: An element could not be located on the page using the given search parameters.


